<?xml version="1.0" encoding="UTF-8"?>
<robot generator="Robot 3.0.4 (Python 3.7.0 on win32)" generated="20181015 11:06:46.150">
<suite id="s1" name="wallet getWalletByUid Get" source="C:\Users\ShadowMimosa\Desktop\STU\Top\Lib\mappapi\wallet\wallet_getWalletByUid_Get.txt">
<test id="s1-t1" name="Class_01">
<kw name="wallet_getWalletByUid_Get_Keywords">
<doc>wallet/getWalletByUid 接口用例的Keywords关健字</doc>
<arguments>
<arg>0</arg>
<arg>成功</arg>
</arguments>
<msg timestamp="20181015 11:06:46.279" level="FAIL">Keyword 'wallet_getWalletByUid_Get_Keywords' expected 3 arguments, got 2.</msg>
<status status="FAIL" starttime="20181015 11:06:46.279" endtime="20181015 11:06:46.279"></status>
</kw>
<doc>wallet/getWalletByUid TestCase测试用例</doc>
<tags>
<tag>auto_v1</tag>
<tag>Test</tag>
</tags>
<status status="FAIL" starttime="20181015 11:06:46.278" endtime="20181015 11:06:46.280" critical="yes">Keyword 'wallet_getWalletByUid_Get_Keywords' expected 3 arguments, got 2.</status>
</test>
<doc>wallet/getWalletByUid 接口脚本</doc>
<status status="FAIL" starttime="20181015 11:06:46.152" endtime="20181015 11:06:46.282"></status>
</suite>
<statistics>
<total>
<stat pass="0" fail="1">Critical Tests</stat>
<stat pass="0" fail="1">All Tests</stat>
</total>
<tag>
<stat pass="0" fail="1">auto_v1</stat>
<stat pass="0" fail="1">Test</stat>
</tag>
<suite>
<stat pass="0" fail="1" id="s1" name="wallet getWalletByUid Get">wallet getWalletByUid Get</stat>
</suite>
</statistics>
<errors>
<msg timestamp="20181015 11:06:46.259" level="ERROR">Error in test library 'pymysql': Creating keyword 'Connect' failed: Keyword with same name defined multiple times.</msg>
<msg timestamp="20181015 11:06:46.274" level="ERROR">Error in file 'C:\Users\ShadowMimosa\Desktop\STU\Top\Lib\mappapi\wallet\wallet_getWalletByUid_Get.txt': Importing test library 'HttpLibrary.HTTP' failed: SyntaxError: invalid syntax (__init__.py, line 16)
Traceback (most recent call last):
  None
PYTHONPATH:
  C:\Users\ShadowMimosa\Desktop\STU\Top\Lib\mappapi\wallet
  C:\Users\ShadowMimosa\AppData\Local\Programs\Python\Python37\python37.zip
  C:\Users\ShadowMimosa\AppData\Local\Programs\Python\Python37\DLLs
  C:\Users\ShadowMimosa\AppData\Local\Programs\Python\Python37\lib
  C:\Users\ShadowMimosa\AppData\Local\Programs\Python\Python37
  C:\Users\ShadowMimosa\AppData\Roaming\Python\Python37\site-packages
  C:\Users\ShadowMimosa\AppData\Local\Programs\Python\Python37\lib\site-packages
  C:\Users\ShadowMimosa\AppData\Local\Programs\Python\Python37\lib\site-packages\robotframework-3.0.4-py3.7.egg</msg>
<msg timestamp="20181015 11:06:46.276" level="ERROR">Error in file 'C:\Users\ShadowMimosa\Desktop\STU\Top\Lib\mappapi\wallet\wallet_getWalletByUid_Get.txt': Test library '..\Public\Lib\tools_library.py' does not exist.</msg>
<msg timestamp="20181015 11:06:46.277" level="ERROR">Error in file 'C:\Users\ShadowMimosa\Desktop\STU\Top\Lib\mappapi\wallet\wallet_getWalletByUid_Get.txt': Resource file '..\Public\public_lib.txt' does not exist.</msg>
</errors>
</robot>
